<robot
  name="duckiebot_new1228">
  <link
    name="base_link">
    <inertial>
      <origin
        xyz="-0.0101024393214371 2.77555756156289E-17 -0.00724903839291099"
        rpy="0 0 0" />
      <mass
        value="0.224144467859455" />
      <inertia
        ixx="0.000262333315558155"
        ixy="-9.46739929586217E-20"
        ixz="1.25847877839234E-05"
        iyy="0.000594458638144052"
        iyz="3.28272538130837E-20"
        izz="0.000839695132659337" />
    </inertial>
    <visual>
      <origin
        xyz="0 0 0"
        rpy="0 0 0" />
      <geometry>
        <mesh
          filename="package://duckiebot_new1228/meshes/base_link.STL" />
      </geometry>
      <material
        name="">
        <color
          rgba="0.792156862745098 0.819607843137255 0.933333333333333 1" />
      </material>
    </visual>
    <collision>
      <origin
        xyz="0 0 0"
        rpy="0 0 0" />
      <geometry>
        <mesh
          filename="package://duckiebot_new1228/meshes/base_link.STL" />
      </geometry>
    </collision>
  </link>
  <link
    name="lwheel_link">
    <inertial>
      <origin
        xyz="-8.32667268468867E-17 0.0100000000000001 -1.38777878078145E-17"
        rpy="0 0 0" />
      <mass
        value="0.0557789775644867" />
      <inertia
        ixx="1.45803923229503E-05"
        ixy="-1.99984150579823E-21"
        ixz="1.05546145898492E-21"
        iyy="2.54421861416015E-05"
        iyz="-3.05243290373849E-21"
        izz="1.45803923229503E-05" />
    </inertial>
    <visual>
      <origin
        xyz="0 0 0"
        rpy="0 0 0" />
      <geometry>
        <mesh
          filename="package://duckiebot_new1228/meshes/lwheel_link.STL" />
      </geometry>
      <material
        name="">
        <color
          rgba="0.792156862745098 0.819607843137255 0.933333333333333 1" />
      </material>
    </visual>
    <collision>
      <origin
        xyz="0 0 0"
        rpy="0 0 0" />
      <geometry>
        <mesh
          filename="package://duckiebot_new1228/meshes/lwheel_link.STL" />
      </geometry>
    </collision>
  </link>
  <joint
    name="lwheel_joint"
    type="continuous">
    <origin
      xyz="0.037 -0.0760000000000001 -0.02"
      rpy="0 0 0" />
    <parent
      link="base_link" />
    <child
      link="lwheel_link" />
    <axis
      xyz="0 -1 0" />
  </joint>
  <link
    name="rwheel_link">
    <inertial>
      <origin
        xyz="-2.77555756156289E-17 -0.01 -2.77555756156289E-17"
        rpy="0 0 0" />
      <mass
        value="0.0557789775644868" />
      <inertia
        ixx="1.45803923229503E-05"
        ixy="4.60062935577484E-21"
        ixz="-6.46471806336693E-23"
        iyy="2.54421861416015E-05"
        iyz="-3.87738072626345E-21"
        izz="1.45803923229503E-05" />
    </inertial>
    <visual>
      <origin
        xyz="0 0 0"
        rpy="0 0 0" />
      <geometry>
        <mesh
          filename="package://duckiebot_new1228/meshes/rwheel_link.STL" />
      </geometry>
      <material
        name="">
        <color
          rgba="0.792156862745098 0.819607843137255 0.933333333333333 1" />
      </material>
    </visual>
    <collision>
      <origin
        xyz="0 0 0"
        rpy="0 0 0" />
      <geometry>
        <mesh
          filename="package://duckiebot_new1228/meshes/rwheel_link.STL" />
      </geometry>
    </collision>
  </link>
  <joint
    name="rwheel_joint"
    type="continuous">
    <origin
      xyz="0.037 0.076 -0.02"
      rpy="0 0 0" />
    <parent
      link="base_link" />
    <child
      link="rwheel_link" />
    <axis
      xyz="0 -1 0" />
  </joint>
  <link
    name="wheelconnect_link">
    <inertial>
      <origin
        xyz="1.71871205486727E-05 2.77555756156289E-17 -0.00889129340051437"
        rpy="0 0 0" />
      <mass
        value="0.00913938040025901" />
      <inertia
        ixx="1.60355093188034E-06"
        ixy="-7.73413872737081E-23"
        ixz="1.58787191951214E-09"
        iyy="1.10422623295413E-06"
        iyz="1.24825890806269E-22"
        izz="1.79481242782248E-06" />
    </inertial>
    <visual>
      <origin
        xyz="0 0 0"
        rpy="0 0 0" />
      <geometry>
        <mesh
          filename="package://duckiebot_new1228/meshes/wheelconnect_link.STL" />
      </geometry>
      <material
        name="">
        <color
          rgba="0.792156862745098 0.819607843137255 0.933333333333333 1" />
      </material>
    </visual>
    <collision>
      <origin
        xyz="0 0 0"
        rpy="0 0 0" />
      <geometry>
        <mesh
          filename="package://duckiebot_new1228/meshes/wheelconnect_link.STL" />
      </geometry>
    </collision>
  </link>
  <joint
    name="connect_joint"
    type="continuous">
    <origin
      xyz="-0.087 0 -0.021"
      rpy="-5.39137043987863E-16 -2.12238359091467E-18 -0.00393661064679745" />
    <parent
      link="base_link" />
    <child
      link="wheelconnect_link" />
    <axis
      xyz="0 0 1" />
  </joint>
  <link
    name="swheel_link">
    <inertial>
      <origin
        xyz="3.0140820395097E-17 -0.00500000000000003 6.93889390390723E-18"
        rpy="0 0 0" />
      <mass
        value="0.0031101767270539" />
      <inertia
        ixx="1.04450101750227E-07"
        ixy="-2.25665210862123E-23"
        ixz="-1.86856433439062E-23"
        iyy="1.57063924716222E-07"
        iyz="5.78702483149728E-23"
        izz="1.04450101750227E-07" />
    </inertial>
    <visual>
      <origin
        xyz="0 0 0"
        rpy="0 0 0" />
      <geometry>
        <mesh
          filename="package://duckiebot_new1228/meshes/swheel_link.STL" />
      </geometry>
      <material
        name="">
        <color
          rgba="0.792156862745098 0.819607843137255 0.933333333333333 1" />
      </material>
    </visual>
    <collision>
      <origin
        xyz="0 0 0"
        rpy="0 0 0" />
      <geometry>
        <mesh
          filename="package://duckiebot_new1228/meshes/swheel_link.STL" />
      </geometry>
    </collision>
  </link>
  <joint
    name="swheel_joint"
    type="continuous">
    <origin
      xyz="-0.00500000000000001 0.005 -0.019"
      rpy="-9.86076131526265E-32 0 5.8113236445223E-17" />
    <parent
      link="wheelconnect_link" />
    <child
      link="swheel_link" />
    <axis
      xyz="0 -1 0" />
  </joint>
</robot>